{
 "cells": [
  {
   "cell_type": "code",
   "execution_count": 5,
   "metadata": {},
   "outputs": [
    {
     "name": "stdout",
     "output_type": "stream",
     "text": [
      "Found 70 files belonging to 4 classes.\n",
      "Using 56 files for training.\n"
     ]
    },
    {
     "name": "stderr",
     "output_type": "stream",
     "text": [
      "c:\\Users\\Nicollas Fernandes\\AppData\\Local\\Programs\\Python\\Python312\\Lib\\site-packages\\keras\\src\\backend\\tensorflow\\nn.py:602: UserWarning: \"`sparse_categorical_crossentropy` received `from_logits=True`, but the `output` argument was produced by a Softmax activation and thus does not represent logits. Was this intended?\n",
      "  output, from_logits = _get_logits(\n"
     ]
    },
    {
     "ename": "InvalidArgumentError",
     "evalue": "Graph execution error:\n\nDetected at node decode_image/DecodeImage defined at (most recent call last):\n<stack traces unavailable>\n`channels` must be 0, 3 or 4 for BMP, but got 1\n\t [[{{node decode_image/DecodeImage}}]]\n\t [[IteratorGetNext]] [Op:__inference_one_step_on_iterator_3656]",
     "output_type": "error",
     "traceback": [
      "\u001b[1;31m---------------------------------------------------------------------------\u001b[0m",
      "\u001b[1;31mInvalidArgumentError\u001b[0m                      Traceback (most recent call last)",
      "Cell \u001b[1;32mIn[5], line 24\u001b[0m\n\u001b[0;32m     13\u001b[0m test_ds \u001b[38;5;241m=\u001b[39m tensorflow\u001b[38;5;241m.\u001b[39mkeras\u001b[38;5;241m.\u001b[39mpreprocessing\u001b[38;5;241m.\u001b[39mimage_dataset_from_directory(\n\u001b[0;32m     14\u001b[0m     test_data_dir,\n\u001b[0;32m     15\u001b[0m     validation_split\u001b[38;5;241m=\u001b[39m\u001b[38;5;241m0.2\u001b[39m,\n\u001b[1;32m   (...)\u001b[0m\n\u001b[0;32m     20\u001b[0m     batch_size\u001b[38;5;241m=\u001b[39m\u001b[38;5;241m64\u001b[39m\n\u001b[0;32m     21\u001b[0m )\n\u001b[0;32m     23\u001b[0m \u001b[38;5;66;03m# Avaliar o modelo\u001b[39;00m\n\u001b[1;32m---> 24\u001b[0m test_loss, test_accuracy \u001b[38;5;241m=\u001b[39m \u001b[43mmodel\u001b[49m\u001b[38;5;241;43m.\u001b[39;49m\u001b[43mevaluate\u001b[49m\u001b[43m(\u001b[49m\u001b[43mtest_ds\u001b[49m\u001b[43m,\u001b[49m\u001b[43m \u001b[49m\u001b[43mverbose\u001b[49m\u001b[38;5;241;43m=\u001b[39;49m\u001b[38;5;241;43m2\u001b[39;49m\u001b[43m)\u001b[49m\n\u001b[0;32m     26\u001b[0m \u001b[38;5;28mprint\u001b[39m(\u001b[38;5;124mf\u001b[39m\u001b[38;5;124m'\u001b[39m\u001b[38;5;124mTest Accuracy: \u001b[39m\u001b[38;5;132;01m{\u001b[39;00mtest_accuracy\u001b[38;5;132;01m:\u001b[39;00m\u001b[38;5;124m.4f\u001b[39m\u001b[38;5;132;01m}\u001b[39;00m\u001b[38;5;124m'\u001b[39m)\n\u001b[0;32m     27\u001b[0m \u001b[38;5;28mprint\u001b[39m(\u001b[38;5;124mf\u001b[39m\u001b[38;5;124m'\u001b[39m\u001b[38;5;124mTest Loss: \u001b[39m\u001b[38;5;132;01m{\u001b[39;00mtest_loss\u001b[38;5;132;01m:\u001b[39;00m\u001b[38;5;124m.4f\u001b[39m\u001b[38;5;132;01m}\u001b[39;00m\u001b[38;5;124m'\u001b[39m)\n",
      "File \u001b[1;32mc:\\Users\\Nicollas Fernandes\\AppData\\Local\\Programs\\Python\\Python312\\Lib\\site-packages\\keras\\src\\utils\\traceback_utils.py:122\u001b[0m, in \u001b[0;36mfilter_traceback.<locals>.error_handler\u001b[1;34m(*args, **kwargs)\u001b[0m\n\u001b[0;32m    119\u001b[0m     filtered_tb \u001b[38;5;241m=\u001b[39m _process_traceback_frames(e\u001b[38;5;241m.\u001b[39m__traceback__)\n\u001b[0;32m    120\u001b[0m     \u001b[38;5;66;03m# To get the full stack trace, call:\u001b[39;00m\n\u001b[0;32m    121\u001b[0m     \u001b[38;5;66;03m# `keras.config.disable_traceback_filtering()`\u001b[39;00m\n\u001b[1;32m--> 122\u001b[0m     \u001b[38;5;28;01mraise\u001b[39;00m e\u001b[38;5;241m.\u001b[39mwith_traceback(filtered_tb) \u001b[38;5;28;01mfrom\u001b[39;00m \u001b[38;5;28;01mNone\u001b[39;00m\n\u001b[0;32m    123\u001b[0m \u001b[38;5;28;01mfinally\u001b[39;00m:\n\u001b[0;32m    124\u001b[0m     \u001b[38;5;28;01mdel\u001b[39;00m filtered_tb\n",
      "File \u001b[1;32mc:\\Users\\Nicollas Fernandes\\AppData\\Local\\Programs\\Python\\Python312\\Lib\\site-packages\\tensorflow\\python\\eager\\execute.py:53\u001b[0m, in \u001b[0;36mquick_execute\u001b[1;34m(op_name, num_outputs, inputs, attrs, ctx, name)\u001b[0m\n\u001b[0;32m     51\u001b[0m \u001b[38;5;28;01mtry\u001b[39;00m:\n\u001b[0;32m     52\u001b[0m   ctx\u001b[38;5;241m.\u001b[39mensure_initialized()\n\u001b[1;32m---> 53\u001b[0m   tensors \u001b[38;5;241m=\u001b[39m pywrap_tfe\u001b[38;5;241m.\u001b[39mTFE_Py_Execute(ctx\u001b[38;5;241m.\u001b[39m_handle, device_name, op_name,\n\u001b[0;32m     54\u001b[0m                                       inputs, attrs, num_outputs)\n\u001b[0;32m     55\u001b[0m \u001b[38;5;28;01mexcept\u001b[39;00m core\u001b[38;5;241m.\u001b[39m_NotOkStatusException \u001b[38;5;28;01mas\u001b[39;00m e:\n\u001b[0;32m     56\u001b[0m   \u001b[38;5;28;01mif\u001b[39;00m name \u001b[38;5;129;01mis\u001b[39;00m \u001b[38;5;129;01mnot\u001b[39;00m \u001b[38;5;28;01mNone\u001b[39;00m:\n",
      "\u001b[1;31mInvalidArgumentError\u001b[0m: Graph execution error:\n\nDetected at node decode_image/DecodeImage defined at (most recent call last):\n<stack traces unavailable>\n`channels` must be 0, 3 or 4 for BMP, but got 1\n\t [[{{node decode_image/DecodeImage}}]]\n\t [[IteratorGetNext]] [Op:__inference_one_step_on_iterator_3656]"
     ]
    }
   ],
   "source": [
    "import keras\n",
    "import tensorflow\n",
    "\n",
    "model = keras.models.load_model('C:/Users/Nicollas Fernandes/Documents/Faculdade/IC/Teste_nos_trabalhos_encontrados/circuitnet-master/treinamento1/model.keras')\n",
    "\n",
    "# Carregar o modelo salvo\n",
    "model = keras.models.load_model('C:/Users/Nicollas Fernandes/Documents/Faculdade/IC/Teste_nos_trabalhos_encontrados/circuitnet-master/treinamento1/model.keras')\n",
    "\n",
    "# Diretório dos dados de teste\n",
    "test_data_dir = 'C:/Users/Nicollas Fernandes/Documents/Faculdade/IC/Teste_nos_trabalhos_encontrados/circuitnet-master/treinamento1/data/teste/'\n",
    "\n",
    "# Carregar dados de teste\n",
    "test_ds = tensorflow.keras.preprocessing.image_dataset_from_directory(\n",
    "    test_data_dir,\n",
    "    validation_split=0.2,\n",
    "    subset=\"training\",\n",
    "    seed=123,\n",
    "    color_mode='grayscale',\n",
    "    image_size=(120, 120),  # Use as mesmas dimensões que foram usadas no treinamento\n",
    "    batch_size=64\n",
    ")\n",
    "\n",
    "# Avaliar o modelo\n",
    "test_loss, test_accuracy = model.evaluate(test_ds, verbose=2)\n",
    "\n",
    "print(f'Test Accuracy: {test_accuracy:.4f}')\n",
    "print(f'Test Loss: {test_loss:.4f}')\n"
   ]
  }
 ],
 "metadata": {
  "kernelspec": {
   "display_name": "Python 3",
   "language": "python",
   "name": "python3"
  },
  "language_info": {
   "codemirror_mode": {
    "name": "ipython",
    "version": 3
   },
   "file_extension": ".py",
   "mimetype": "text/x-python",
   "name": "python",
   "nbconvert_exporter": "python",
   "pygments_lexer": "ipython3",
   "version": "3.12.2"
  }
 },
 "nbformat": 4,
 "nbformat_minor": 2
}
